<?xml version="1.0"?>

<robot name="line_follower_robot"
       xmlns:xacro="http://www.ros.org/wiki/xacro">

  <!-- Include other Xacro files -->
  <xacro:include filename="$(find line_follower_description)/urdf/materials.xacro"/>
  <xacro:include filename="$(find line_follower_description)/urdf/base.xacro"/>

  <!-- ================= LEFT WHEEL ================= -->
  <link name="left_wheel">

    <visual>
      <origin xyz="0 0 0" rpy="1.5708 0 0"/>
      <geometry>
        <cylinder radius="0.05" length="0.03"/>
      </geometry>
      <material name="black"/>
    </visual>

    <collision>
      <origin xyz="0 0 0" rpy="1.5708 0 0"/>
      <geometry>
        <cylinder radius="0.05" length="0.03"/>
      </geometry>
    </collision>

    <inertial>
      <mass value="0.3"/>
      <origin xyz="0 0 0"/>
      <inertia
        ixx="0.001"
        iyy="0.001"
        izz="0.001"
        ixy="0"
        ixz="0"
        iyz="0"/>
    </inertial>

  </link>

  <!-- ================= RIGHT WHEEL ================= -->
  <link name="right_wheel">

    <visual>
      <origin xyz="0 0 0" rpy="1.5708 0 0"/>
      <geometry>
        <cylinder radius="0.05" length="0.03"/>
      </geometry>
      <material name="black"/>
    </visual>

    <collision>
      <origin xyz="0 0 0" rpy="1.5708 0 0"/>
      <geometry>
        <cylinder radius="0.05" length="0.03"/>
      </geometry>
    </collision>

    <inertial>
      <mass value="0.3"/>
      <origin xyz="0 0 0"/>
      <inertia
        ixx="0.001"
        iyy="0.001"
        izz="0.001"
        ixy="0"
        ixz="0"
        iyz="0"/>
    </inertial>

  </link>

  <!-- ================= LEFT WHEEL JOINT ================= -->
  <joint name="left_wheel_joint" type="continuous">
    <parent link="base_link"/>
    <child link="left_wheel"/>
    <origin xyz="0 0.11 -0.025" rpy="0 0 0"/>
    <axis xyz="0 1 0"/>
  </joint>

  <!-- ================= RIGHT WHEEL JOINT ================= -->
  <joint name="right_wheel_joint" type="continuous">
    <parent link="base_link"/>
    <child link="right_wheel"/>
    <origin xyz="0 -0.11 -0.025" rpy="0 0 0"/>
    <axis xyz="0 1 0"/>
  </joint>

</robot>