<?xml version="1.0"?>

<robot xmlns:xacro="http://www.ros.org/wiki/xacro">

    <xacro:macro name="wheel" params="prefix y_position">
        <link name="${prefix}_wheel">

  <visual>
    <origin xyz="0 0 0" rpy="1.5708 0 0"/>

    <geometry>
      <cylinder radius="0.05" length="0.03"/>
    </geometry>

    <material name="black"/>
  </visual>

  <collision>
    <origin xyz="0 0 0" rpy="1.5708 0 0"/>

    <geometry>
      <cylinder radius="0.05" length="0.03"/>
    </geometry>
  </collision>

  <inertial>
    <mass value="0.3"/>

    <origin xyz="0 0 0"/>

    <inertia
      ixx="0.001"
      iyy="0.001"
      izz="0.001"
      ixy="0"
      ixz="0"
      iyz="0"/>
  </inertial>

</link>
<joint name="${prefix}_wheel_joint" type="continuous">

  <parent link="base_link"/>

  <child link="${prefix}_wheel"/>

  <origin xyz="0 ${y_position} -0.025" rpy="0 0 0"/>

  <axis xyz="0 1 0"/>

</joint>

    </xacro:macro>

</robot>